<?xml version="1.0" encoding="utf-8"?>

<robot
  name="rover" xmlns:xacro="http://www.ros.org/wiki/xacro">

  <!-- <link name="dummy_link">
    
  </link> -->

  <link
    name="base_link">
    <inertial>
      <origin
        xyz="-0.00013831907102568 1.72081362193362E-11 0.00312541383867626"
        rpy="0 0 0" />
      <mass
        value="0.841217991440235" />
      <inertia
        ixx="0.00029048014505705"
        ixy="-9.55160061707672E-10"
        ixz="1.5155822937521E-05"
        iyy="0.00136894323138028"
        iyz="-4.51615469448788E-12"
        izz="0.00140614084506565" />
    </inertial>

    <visual>
      <origin
        xyz="0 0 0"
        rpy="0 0 0" />
      <geometry>
        <mesh
          filename="file:///home/anonymous/project_ws/src/rover/meshes/base_link.STL" />
      </geometry>
      <material
        name="">
        <color
          rgba="0.792156862745098 0.819607843137255 0.933333333333333 1" />
      </material>
    </visual>
    <collision>
      <origin
        xyz="0 0 0"
        rpy="0 0 0" />
      <geometry>
        <mesh
          filename="file:///home/anonymous/project_ws/src/rover/meshes/base_link.STL" />
      </geometry>
    </collision>
  </link>

  <!-- <joint name="dummy_joint" type="fixed">
      <parent link="dummy_link"/>
      <child link="base_link"/>
        
  </joint> -->

  <link
    name="front_right_wheel">
    <inertial>
      <origin
        xyz="-1.02049202421739E-11 4.52816655699406E-11 -0.0188572675950841"
        rpy="0 0 0" />
      <mass
        value="0.0169810669319342" />
      <inertia
        ixx="6.69284231029886E-06"
        ixy="-2.3593534204749E-14"
        ixz="3.38705114836052E-14"
        iyy="6.69284231027905E-06"
        iyz="8.02048076338983E-15"
        izz="9.06807752001078E-06" />
    </inertial>
    <visual>
      <origin
        xyz="0 0 0"
        rpy="0 0 0" />
      <geometry>
        <mesh
          filename="file:///home/anonymous/project_ws/src/rover/meshes/front_right_wheel.STL" />
      </geometry>
      <material
        name="">
        <color
          rgba="0.792156862745098 0.819607843137255 0.933333333333333 1" />
      </material>
    </visual>
    <collision>
      <origin
        xyz="0 0 0"
        rpy="0 0 0" />
      <geometry>
        <mesh
          filename="file:///home/anonymous/project_ws/src/rover/meshes/front_right_wheel.STL" />
      </geometry>
    </collision>
  </link>

  <joint
    name="base_link_to_front_right_wheel"
    type="continuous">
    <origin
      xyz="0.117290515707591 -0.127 -0.025435192502925"
      rpy="1.5707963267949 -1.5707963267949 0" />
    <parent
      link="base_link" />
    <child
      link="front_right_wheel" />
    <axis
      xyz="0 0 -1" />
  </joint>

  <link
    name="front_left_wheel">
    <inertial>
      <origin
        xyz="1.02049063643861E-11 4.52816638352171E-11 -0.018857267595084"
        rpy="0 0 0" />
      <mass
        value="0.0169810669319342" />
      <inertia
        ixx="6.69284231029887E-06"
        ixy="2.35935343554851E-14"
        ixz="-3.38705125007288E-14"
        iyy="6.69284231027906E-06"
        iyz="8.02048279684241E-15"
        izz="9.06807752001078E-06" />
    </inertial>
    <visual>
      <origin
        xyz="0 0 0"
        rpy="0 0 0" />
      <geometry>
        <mesh
          filename="file:///home/anonymous/project_ws/src/rover/meshes/front_left_wheel.STL" />
      </geometry>
      <material
        name="">
        <color
          rgba="0.792156862745098 0.819607843137255 0.933333333333333 1" />
      </material>
    </visual>
    <collision>
      <origin
        xyz="0 0 0"
        rpy="0 0 0" />
      <geometry>
        <mesh
          filename="file:///home/anonymous/project_ws/src/rover/meshes/front_left_wheel.STL" />
      </geometry>
    </collision>
  </link>
  <joint
    name="base_link_to_front_left_wheel"
    type="continuous">
    <origin
      xyz="0.11659 0.127 -0.015104"
      rpy="1.5708 0 3.1416" />
    <parent
      link="base_link" />
    <child
      link="front_left_wheel" />
    <axis
      xyz="0 0 -1" />
  </joint>
  <link
    name="bottom_right_wheel">
    <inertial>
      <origin
        xyz="-3.26679794326878E-11 -3.29753377381614E-11 -0.018857267595084"
        rpy="0 0 0" />
      <mass
        value="0.0169810669319342" />
      <inertia
        ixx="6.69284228887819E-06"
        ixy="9.91131174432663E-15"
        ixz="-2.49917716423862E-14"
        iyy="6.69284233169973E-06"
        iyz="2.42270662118507E-14"
        izz="9.06807752001078E-06" />
    </inertial>
    <visual>
      <origin
        xyz="0 0 0"
        rpy="0 0 0" />
      <geometry>
        <mesh
          filename="file:///home/anonymous/project_ws/src/rover/meshes/bottom_right_wheel.STL" />
      </geometry>
      <material
        name="">
        <color
          rgba="0.792156862745098 0.819607843137255 0.933333333333333 1" />
      </material>
    </visual>
    <collision>
      <origin
        xyz="0 0 0"
        rpy="0 0 0" />
      <geometry>
        <mesh
          filename="file:///home/anonymous/project_ws/src/rover/meshes/bottom_right_wheel.STL" />
      </geometry>
    </collision>
  </link>

  <joint
    name="base_link_to_bottom_right_wheel"
    type="continuous">
    <origin
      xyz="-0.1177 -0.127 -0.011032"
      rpy="1.5708 0 0" />
    <parent
      link="base_link" />
    <child
      link="bottom_right_wheel" />
    <axis
      xyz="0 0 -1" />
  </joint>

  <link
    name="bottom_left_wheel">
    <inertial>
      <origin
        xyz="3.26679933104757E-11 -3.29753464117788E-11 -0.018857267595084"
        rpy="0 0 0" />
      <mass
        value="0.0169810669319342" />
      <inertia
        ixx="6.69284228887819E-06"
        ixy="-9.91131071353208E-15"
        ixz="2.49917735058932E-14"
        iyy="6.69284233169972E-06"
        iyz="2.42270622702387E-14"
        izz="9.06807752001077E-06" />
    </inertial>
    <visual>
      <origin
        xyz="0 0 0"
        rpy="0 0 0" />
      <geometry>
        <mesh
          filename="file:///home/anonymous/project_ws/src/rover/meshes/bottom_left_wheel.STL" />
      </geometry>
      <material
        name="">
        <color
          rgba="0.792156862745098 0.819607843137255 0.933333333333333 1" />
      </material>
    </visual>
    <collision>
      <origin
        xyz="0 0 0"
        rpy="0 0 0" />
      <geometry>
        <mesh
          filename="file:///home/anonymous/project_ws/src/rover/meshes/bottom_left_wheel.STL" />
      </geometry>
    </collision>
  </link>
  <joint
    name="base_link_to_bottom_left_wheel"
    type="continuous">
    <origin
      xyz="-0.1177 0.127 -0.011032"
      rpy="1.5708 0 3.1416" />
    <parent
      link="base_link" />
    <child
      link="bottom_left_wheel" />
    <axis
      xyz="0 0 -1" />
  </joint>
</robot>