<?xml version="1.0" encoding="utf-8"?>
<!-- This URDF was automatically created by SolidWorks to URDF Exporter! Originally created by Stephen Brawner (brawner@gmail.com) 
     Commit Version: 1.6.0-4-g7f85cfe  Build Version: 1.6.7995.38578
     For more information, please see http://wiki.ros.org/sw_urdf_exporter -->
<robot
  name="Tracked-3">
  <link
    name="base_link">
    <inertial>
      <origin
        xyz="0.00130991626705053 3.49863639654621E-08 -0.00547333121816359"
        rpy="0 0 0" />
      <mass
        value="0.84121706270277" />
      <inertia
        ixx="0.000471900739611814"
        ixy="-2.09182785151148E-08"
        ixz="-1.51956152423411E-05"
        iyy="0.00136894339262334"
        iyz="7.11926294463084E-07"
        izz="0.00158904161906431" />
    </inertial>
    <visual>
      <origin
        xyz="0 0 0"
        rpy="0 0 0" />
      <geometry>
        <mesh
          filename="file:///home/anonymous/project_ws/src/rover/meshes/base_link.STL" />
      </geometry>
      <material
        name="">
        <color
          rgba="0.752941176470588 0.752941176470588 0.752941176470588 1" />
      </material>
    </visual>
    <collision>
      <origin
        xyz="0 0 0"
        rpy="0 0 0" />
      <geometry>
        <mesh
          filename="file:///home/anonymous/project_ws/src/rover/meshes/base_link.STL" />
      </geometry>
    </collision>
  </link>
  
  <link
    name="front_right_wheel">
    <inertial>
      <origin
        xyz="-8.80747558218431E-12 -4.55740722937747E-11 -0.018857267595084"
        rpy="0 0 0" />
      <mass
        value="0.0169810669319342" />
      <inertia
        ixx="6.69284229296302E-06"
        ixy="-1.60145736127304E-14"
        ixz="-3.42445122120506E-14"
        iyy="6.69284232761491E-06"
        iyz="6.23321834661461E-15"
        izz="9.06807752001079E-06" />
    </inertial>
    <visual>
      <origin
        xyz="0 0 0"
        rpy="0 0 0" />
      <geometry>
        <mesh
          filename="file:///home/anonymous/project_ws/src/rover/meshes/front_right_wheel.STL" />
      </geometry>
      <material
        name="">
        <color
          rgba="1 1 1 1" />
      </material>
    </visual>
    <collision>
      <origin
        xyz="0 0 0"
        rpy="0 0 0" />
      <geometry>
        <mesh
          filename="file:///home/anonymous/project_ws/src/rover/meshes/front_right_wheel.STL" />
      </geometry>
    </collision>
  </link>

  <joint
    name="base_link_to_front_right_wheel"
    type="continuous">
    <origin
      xyz="0.11729 -0.127 -0.025435"
      rpy="1.5708 -1.5708 0" />
    <parent
      link="base_link" />
    <child
      link="front_right_wheel" />
    <axis
      xyz="0 0 -1" />
  </joint>

  <link
    name="front_left_wheel">
    <inertial>
      <origin
        xyz="-3.26679655549E-11 -3.29753273298206E-11 -0.018857267595084"
        rpy="0 0 0" />
      <mass
        value="0.0169810669319342" />
      <inertia
        ixx="6.6928422888782E-06"
        ixy="9.91131187080384E-15"
        ixz="-2.49917726913834E-14"
        iyy="6.69284233169973E-06"
        iyz="2.42270670184219E-14"
        izz="9.06807752001078E-06" />
    </inertial>
    <visual>
      <origin
        xyz="0 0 0"
        rpy="0 0 0" />
      <geometry>
        <mesh
          filename="file:///home/anonymous/project_ws/src/rover/meshes/front_left_wheel.STL" />
      </geometry>
      <material
        name="">
        <color
          rgba="1 1 1 1" />
      </material>
    </visual>
    <collision>
      <origin
        xyz="0 0 0"
        rpy="0 0 0" />
      <geometry>
        <mesh
          filename="file:///home/anonymous/project_ws/src/rover/meshes/front_left_wheel.STL" />
      </geometry>
    </collision>
  </link>

  <joint
    name="base_link_to_front_left_wheel"
    type="continuous">
    <origin
      xyz="0.11886 0.127 -0.019032"
      rpy="1.5708 0 3.1416" />
    <parent
      link="base_link" />
    <child
      link="front_left_wheel" />
    <axis
      xyz="0 0 -1" />
  </joint>

  <link
    name="bottom_right_wheel">
    <inertial>
      <origin
        xyz="2.91839191701726E-11 -3.60952205624709E-11 -0.018857267595084"
        rpy="0 0 0" />
      <mass
        value="0.0169810669319343" />
      <inertia
        ixx="6.69284232901609E-06"
        ixy="-1.43509531574459E-14"
        ixz="-2.68277880972272E-14"
        iyy="6.69284229156184E-06"
        iyz="-2.21767763493592E-14"
        izz="9.06807752001078E-06" />
    </inertial>
    <visual>
      <origin
        xyz="0 0 0"
        rpy="0 0 0" />
      <geometry>
        <mesh
          filename="file:///home/anonymous/project_ws/src/rover/meshes/bottom_right_wheel.STL" />
      </geometry>
      <material
        name="">
        <color
          rgba="1 1 1 1" />
      </material>
    </visual>
    <collision>
      <origin
        xyz="0 0 0"
        rpy="0 0 0" />
      <geometry>
        <mesh
          filename="file:///home/anonymous/project_ws/src/rover/meshes/bottom_right_wheel.STL" />
      </geometry>
    </collision>
  </link>

  <joint
    name="base_link_bottom_right_wheel"
    type="continuous">
    <origin
      xyz="-0.11353 -0.127 -0.029416"
      rpy="1.5708 0 0" />
    <parent
      link="base_link" />
    <child
      link="bottom_right_wheel" />
    <axis
      xyz="0 0 -1" />
  </joint>

  <link
    name="bottom_left_wheel">
    <inertial>
      <origin
        xyz="-1.02049202421739E-11 4.5281641283812E-11 -0.0188572675950841"
        rpy="0 0 0" />
      <mass
        value="0.0169810669319342" />
      <inertia
        ixx="6.69284231029886E-06"
        ixy="-2.35935358902678E-14"
        ixz="3.38705123274362E-14"
        iyy="6.69284231027905E-06"
        iyz="8.02048069556269E-15"
        izz="9.06807752001078E-06" />
    </inertial>
    <visual>
      <origin
        xyz="0 0 0"
        rpy="0 0 0" />
      <geometry>
        <mesh
          filename="file:///home/anonymous/project_ws/src/rover/meshes/bottom_left_wheel.STL" />
      </geometry>
      <material
        name="">
        <color
          rgba="1 1 1 1" />
      </material>
    </visual>
    <collision>
      <origin
        xyz="0 0 0"
        rpy="0 0 0" />
      <geometry>
        <mesh
          filename="file:///home/anonymous/project_ws/src/rover/meshes/bottom_left_wheel.STL" />
      </geometry>
    </collision>
  </link>

  <joint
    name="base_link_to_bottom_left_wheel"
    type="continuous">
    <origin
      xyz="-0.11544 0.127 -0.023104"
      rpy="1.5708 0 3.1416" />
    <parent
      link="base_link" />
    <child
      link="bottom_left_wheel" />
    <axis
      xyz="0 0 -1" />
  </joint>

</robot>