<?xml version="1.0" encoding="utf-8"?>
<!-- This URDF was automatically created by SolidWorks to URDF Exporter! Originally created by Stephen Brawner (brawner@gmail.com) 
     Commit Version: 1.6.0-4-g7f85cfe  Build Version: 1.6.7995.38578
     For more information, please see http://wiki.ros.org/sw_urdf_exporter -->
<robot
  name="tracked_with_tread">
  <link
    name="base_link">
    <inertial>
      <origin
        xyz="0.00130991626705054 3.49863639634E-08 -0.00547333121816359"
        rpy="0 0 0" />
      <mass
        value="0.84121706270277" />
      <inertia
        ixx="0.000471900739611814"
        ixy="-2.09182785151148E-08"
        ixz="-1.51956152423411E-05"
        iyy="0.00136894339262334"
        iyz="7.11926294463081E-07"
        izz="0.00158904161906431" />
    </inertial>
    <visual>
      <origin
        xyz="0 0 0"
        rpy="0 0 0" />
      <geometry>
        <mesh
          filename="file:///home/anonymous/project_ws/src/rover/meshes/base_link.STL" />
      </geometry>
      <material
        name="">
        <color
          rgba="0.752941176470588 0.752941176470588 0.752941176470588 1" />
      </material>
    </visual>
    <collision>
      <origin
        xyz="0 0 0"
        rpy="0 0 0" />
      <geometry>
        <mesh
          filename="file:///home/anonymous/project_ws/src/rover/meshes/base_link.STL" />
      </geometry>
    </collision>
  </link>
  <link
    name="front_right_wheel">
    <inertial>
      <origin
        xyz="-8.80747905163126E-12 -4.55740861715626E-11 -0.018857267595084"
        rpy="0 0 0" />
      <mass
        value="0.0169810669319342" />
      <inertia
        ixx="6.69284229296301E-06"
        ixy="-1.60145736884105E-14"
        ixz="-3.42445135185028E-14"
        iyy="6.69284232761491E-06"
        iyz="6.23321795831195E-15"
        izz="9.06807752001078E-06" />
    </inertial>
    <visual>
      <origin
        xyz="0 0 0"
        rpy="0 0 0" />
      <geometry>
        <mesh
          filename="file:///home/anonymous/project_ws/src/rover/meshes/front_right_wheel.STL" />
      </geometry>
      <material
        name="">
        <color
          rgba="1 1 1 1" />
      </material>
    </visual>
    <collision>
      <origin
        xyz="0 0 0"
        rpy="0 0 0" />
      <geometry>
        <mesh
          filename="file:///home/anonymous/project_ws/src/rover/meshes/front_right_wheel.STL" />
      </geometry>
    </collision>
  </link>
  <joint
    name="base_link_to_front_right_wheel"
    type="continuous">
    <origin
      xyz="0.117290515707591 -0.127 -0.025435192502925"
      rpy="1.5707963267949 -1.5707963267949 0" />
    <parent
      link="base_link" />
    <child
      link="front_right_wheel" />
    <axis
      xyz="0 0 -1" />
  </joint>
  <link
    name="right_tread">
    <inertial>
      <origin
        xyz="0.00948575511995705 -0.0271678464476261 -1.38777878078145E-17"
        rpy="0 0 0" />
      <mass
        value="0.0467186064325547" />
      <inertia
        ixx="5.36340024147205E-06"
        ixy="8.04600395063009E-10"
        ixz="1.91915450464644E-22"
        iyy="5.40913175843456E-06"
        iyz="6.06624413910749E-22"
        izz="1.12903298878675E-07" />
    </inertial>
    <visual>
      <origin
        xyz="0 0 0"
        rpy="0 0 0" />
      <geometry>
        <mesh
          filename="file:///home/anonymous/project_ws/src/rover/meshes/right_tread.STL" />
      </geometry>
      <material
        name="">
        <color
          rgba="0.298039215686275 0.298039215686275 0.298039215686275 1" />
      </material>
    </visual>
    <collision>
      <origin
        xyz="0 0 0"
        rpy="0 0 0" />
      <geometry>
        <mesh
          filename="file:///home/anonymous/project_ws/src/rover/meshes/right_tread.STL" />
      </geometry>
    </collision>
  </link>
  <joint
    name="front_right_wheel_to_right_tread"
    type="fixed">
    <origin
      xyz="0.031542 0.10643 -0.2335"
      rpy="3.1416 0 1.5708" />
    <parent
      link="base_link" />
    <child
      link="right_tread" />
    <limit lower="0" upper="2" velocity="100" effort="100"/> 
    <axis
      xyz="1 0 0" />   
  </joint>
  <link
    name="front_left_wheel">
    <inertial>
      <origin
        xyz="-3.26679377993244E-11 -3.29753255950971E-11 -0.018857267595084"
        rpy="0 0 0" />
      <mass
        value="0.0169810669319342" />
      <inertia
        ixx="6.69284228887819E-06"
        ixy="9.91131175932832E-15"
        ixz="-2.4991772798552E-14"
        iyy="6.69284233169973E-06"
        iyz="2.42270676688459E-14"
        izz="9.06807752001078E-06" />
    </inertial>
    <visual>
      <origin
        xyz="0 0 0"
        rpy="0 0 0" />
      <geometry>
        <mesh
          filename="file:///home/anonymous/project_ws/src/rover/meshes/front_left_wheel.STL" />
      </geometry>
      <material
        name="">
        <color
          rgba="1 1 1 1" />
      </material>
    </visual>
    <collision>
      <origin
        xyz="0 0 0"
        rpy="0 0 0" />
      <geometry>
        <mesh
          filename="file:///home/anonymous/project_ws/src/rover/meshes/front_left_wheel.STL" />
      </geometry>
    </collision>
  </link>
  <joint
    name="base_link_to_front_left_wheel"
    type="continuous">
    <origin
      xyz="0.11886 0.127 -0.019032"
      rpy="1.5708 0 3.1416" />
    <parent
      link="base_link" />
    <child
      link="front_left_wheel" />
    <axis
      xyz="0 0 -1" />
  </joint>
  <link
    name="bottom_right_wheel">
    <inertial>
      <origin
        xyz="2.91839469257482E-11 -3.60952205624709E-11 -0.018857267595084"
        rpy="0 0 0" />
      <mass
        value="0.0169810669319343" />
      <inertia
        ixx="6.69284232901609E-06"
        ixy="-1.4350953219646E-14"
        ixz="-2.68277877476378E-14"
        iyy="6.69284229156184E-06"
        iyz="-2.21767763368758E-14"
        izz="9.06807752001078E-06" />
    </inertial>
    <visual>
      <origin
        xyz="0 0 0"
        rpy="0 0 0" />
      <geometry>
        <mesh
          filename="file:///home/anonymous/project_ws/src/rover/meshes/bottom_right_wheel.STL" />
      </geometry>
      <material
        name="">
        <color
          rgba="1 1 1 1" />
      </material>
    </visual>
    <collision>
      <origin
        xyz="0 0 0"
        rpy="0 0 0" />
      <geometry>
        <mesh
          filename="file:///home/anonymous/project_ws/src/rover/meshes/bottom_right_wheel.STL" />
      </geometry>
    </collision>
  </link>
  <joint
    name="base_link_bottom_right_wheel"
    type="continuous">
    <origin
      xyz="-0.11353 -0.127 -0.029416"
      rpy="1.5708 0 0" />
    <parent
      link="base_link" />
    <child
      link="bottom_right_wheel" />
    <axis
      xyz="0 0 -1" />
  </joint>
  <link
    name="bottom_left_wheel">
    <inertial>
      <origin
        xyz="-1.02049202421739E-11 4.52816447532589E-11 -0.018857267595084"
        rpy="0 0 0" />
      <mass
        value="0.0169810669319342" />
      <inertia
        ixx="6.69284231029886E-06"
        ixy="-2.35935358405885E-14"
        ixz="3.38705122382542E-14"
        iyy="6.69284231027905E-06"
        iyz="8.0204812430973E-15"
        izz="9.06807752001078E-06" />
    </inertial>
    <visual>
      <origin
        xyz="0 0 0"
        rpy="0 0 0" />
      <geometry>
        <mesh
          filename="file:///home/anonymous/project_ws/src/rover/meshes/bottom_left_wheel.STL" />
      </geometry>
      <material
        name="">
        <color
          rgba="1 1 1 1" />
      </material>
    </visual>
    <collision>
      <origin
        xyz="0 0 0"
        rpy="0 0 0" />
      <geometry>
        <mesh
          filename="file:///home/anonymous/project_ws/src/rover/meshes/bottom_left_wheel.STL" />
      </geometry>
    </collision>
  </link>
  <joint
    name="base_link_to_bottom_left_wheel"
    type="continuous">
    <origin
      xyz="-0.115435440029406 0.127 -0.023104093147408"
      rpy="1.5707963267949 0 3.14159265358979" />
    <parent
      link="base_link" />
    <child
      link="bottom_left_wheel" />
    <axis
      xyz="0 0 -1" />
  </joint>
</robot>